<?xml version="1.0"?>
   <robot name="rosrobot">

    <material name="white">
        <color rgba="1 1 1 1"/>
    </material>

    <material name="silver">
        <color rgba="192 192 192 0.6"/>
    </material>

    <material name="black">
        <color rgba="0 0 0 1"/>
    </material>

    <link name="base_link">
      <visual>
        <geometry>
          <box size="0.15 0.14 0.001"/>
        </geometry>
        <origin rpy="0 0 0" xyz="0.0 0.00 -0.03"/>
        <material name="white"/>
      </visual>
    </link>

    <link name="top_base">
      <visual>
        <geometry>
          <box size="0.15 0.14 0.001"/>
        </geometry>
        <origin rpy="0 0 0" xyz="0.0 0.00 0.00"/>        
        <material name="silver"/>
      </visual>
    </link>

    <link name="sideplate_left">
      <visual>
        <geometry>
          <box size="0.17 0.001 0.055"/>
        </geometry>
        <origin rpy="0 0 0" xyz="0.0 0.00 0.00"/>
        <material name="white"/>
      </visual>
    </link>

    <link name="sideplate_right">
      <visual>
        <geometry>
          <box size="0.17 0.001 0.055"/>
        </geometry>
        <origin rpy="0 0 0" xyz="0.0 0.00 0.00"/>
        <material name="white"/>
      </visual>
    </link>

    <link name="wheel_left_back">
      <visual>
        <geometry>
          <cylinder length="0.027" radius="0.0345"/>
        </geometry>
        <origin rpy="1.57 0 0" xyz="0 0 0"/>
        <material name="black"/>
      </visual>
    </link>

    <link name="wheel_left_front">
      <visual>
        <geometry>
          <cylinder length="0.027" radius="0.0345"/>
        </geometry>
        <origin rpy="1.57 0 0" xyz="0 0 0"/>
        <material name="black"/>
      </visual>
    </link>

    <link name="wheel_right_back">
      <visual>
        <geometry>
          <cylinder length="0.027" radius="0.0345"/>
        </geometry>
        <origin rpy="1.57 0 0" xyz="0 0 0"/>
        <material name="black"/>
      </visual>
    </link>

    <link name="wheel_right_front">
      <visual>
        <geometry>
          <cylinder length="0.027" radius="0.0345"/>
        </geometry>
        <origin rpy="1.57 0 0" xyz="0 0 0"/>
        <material name="black"/>
      </visual>
    </link>

    <joint name="base_to_topbase" type="fixed">
      <parent link="base_link"/>
      <child link="top_base"/>
      <origin xyz="0 0 0.03" rpy="0 0 0" />
    </joint>

    <joint name="base_to_sideplate_left" type="fixed">
      <parent link="base_link"/>
      <child link="sideplate_left"/>
      <origin xyz="0 0.07 0" rpy="0 0 0" />
    </joint>

    <joint name="base_to_sideplate_right" type="fixed">
      <parent link="base_link"/>
      <child link="sideplate_right"/>
      <origin xyz="0 -0.07 0" rpy="0 0 0" />
    </joint>

    <joint name="base_to_wheel_left_back" type="continuous">
      <parent link="base_link"/>
      <child link="wheel_left_back"/>
      <origin xyz="-0.080 0.0865 0" rpy="0 0 0" />
      <axis xyz="0 1 0" />
    </joint>

    <joint name="base_to_wheel_left_front" type="continuous">
      <parent link="base_link"/>
      <child link="wheel_left_front"/>
      <origin xyz="0.080 0.0865 0" rpy="0 0 0" />
      <axis xyz="0 1 0" />
    </joint>

    <joint name="base_to_wheel_right_back" type="continuous">
      <parent link="base_link"/>
      <child link="wheel_right_back"/>
      <origin xyz="-0.080 -0.0865 0" rpy="0 0 0" />
      <axis xyz="0 1 0" />
    </joint>

    <joint name="base_to_wheel_right_front" type="continuous">
      <parent link="base_link"/>
      <child link="wheel_right_front"/>
      <origin xyz="0.080 -0.0865 0" rpy="0 0 0" />
      <axis xyz="0 1 0" />
    </joint>

    </robot>